Workbook

Sheet 1. Reports & Sketches
Z4: DOCUMENT ISSUE REGISTER
B5: Project | C5: =Sheet1!C10 -> Aldi Store, Diss
B6: Client | C6: =Sheet1!C11 -> Aldi Stores Ltd | D6: Issue Date
B7: Project No. | C7: =Sheet1!E10 -> 13175
B8: Sheet No. | C8: =RIGHT(CELL("FILENAME",A1),LEN(CELL("FILENAME",A1))-FIND("]",CELL("FILENAME",A1))) -> 1. Reports & Sketches
B10: Document No. | C10: Document Title | D10: Revision
B55: Distribution
B56: Initials | C56: Company | D56: Number of Copies
B70: ViewProjects
C71: Suitability / Issue Status
C72: Format
B73: Key
B74: BS EN ISO 19650 Suitability S0 = WIP Sn = Shared (Non Contractural) An = Published (Contractural) CR = Construction Record
B75: or Issue Status I = Information P = Preliminary T = Tender A = Approval C = Construction B = As Built | K75: Format P = Paper E = Email O = Online D = DWG

Sheet 2. Site & Drainage. 0000-0099
Z4: DOCUMENT ISSUE REGISTER
B5: Project | C5: =Sheet1!C10 -> Aldi Store, Diss
B6: Client | C6: =Sheet1!C11 -> Aldi Stores Ltd | D6: Issue Date
B7: Project No. | C7: =Sheet1!E10 -> 13175 | D7: 11 | E7: 23 | F7: 12 | G7: 28 | H7: 8 | I7: 12 | J7: 31 | K7: 15 | L7: 17 | M7: 22 | N7: 6 | O7: 8 | P7: 25 | Q7: 28 | R7: 28 | S7: 11 | T7: 14 | U7: 5 | V7: 8
B8: Sheet No. | C8: =RIGHT(CELL("FILENAME",A1),LEN(CELL("FILENAME",A1))-FIND("]",CELL("FILENAME",A1))) -> 2. Site & Drainage. 0000-0099 | D8: 4 | E8: 4 | F8: 6 | G8: 6 | H8: 7 | I8: 7 | J8: 7 | K8: 8 | L8: 10 | M8: 10 | N8: 11 | O8: 11 | P8: 11 | Q8: 11 | R8: 11 | S8: 12 | T8: 1 | U8: 2 | V8: 4
D9: 24 | E9: 24 | F9: 24 | G9: 24 | H9: 24 | I9: 24 | J9: 24 | K9: 24 | L9: 24 | M9: 24 | N9: 24 | O9: 24 | P9: 24 | Q9: 24 | R9: 24 | S9: 24 | T9: 25 | U9: 25 | V9: 25
B10: Document No. | C10: Document Title | D10: Revision
B11: CDY-XX-XX-DR-D-Ss_15_10-0001 | C11: PROPOSED LEVELS AND CONTOURS | D11: P01 | E11: C01 | F11: C02 | G11: C03 | J11: C04 | L11: C05 | M11: C06 | O11: C07 | P11: C08 | Q11: C09 | R11: C10 | T11: C11 | U11: C12
B13: CDY-XX-XX-DR-D-Ss_15_10_00-0003 | C13: EXTERNAL WORKS CONSTRUCTION LAYOUT | D13: P01 | E13: C01 | G13: C02 | J13: C03
B14: CDY-XX-XX-DR-D-Ss_15_10_00-0004 | C14: EXTERNAL WORKS CONSTRUCTION DETAILS | D14: P01 | F14: C01 | G14: C02 | J14: C03
B15: CDY-XX-XX-DR-D-Ss_15_10_00-0005 | C15: PROPOSED FORMATION LEVELS AND CONTOURS | K15: P01
B20: CDY-XX-XX-DR-D-Ss_15_10_00-0010 | C20: SUB STATION RC DETAILING | N20: C01
B25: CDY-XX-XX-DR-D-Ss_50_35-0050 | C25: PROPOSED DRAINAGE LAYOUT | E25: C01 | I25: C02 | J25: C03 | S25: C05 | V25: C07
B26: CDY-XX-XX-DR-D-Ss_50_35-0051 | C26: PROPOSED DRAINAGE SCHEDULES | E26: C01 | I26: C02 | J26: C03 | V26: C06
B29: CDY-XX-XX-DR-D-Ss_50_35-0055 | C29: PROPOSED DRAINAGE DETAILS SHEET 1 | E29: C01 | I29: C02 | J29: C03
B30: CDY-XX-XX-DR-D-Ss_50_35-0056 | C30: PROPOSED DRAINAGE DETAILS SHEET 2 | E30: C01 | I30: C02 | J30: C03
B31: CDY-XX-XX-DR-D-Ss_50_35-0057 | C31: PROPOSED DRAINAGE DETAILS SHEET 3 | E31: C01 | I31: C02 | J31: C03
B32: CDY-XX-XX-DR-D-Ss_50_35-0058 | C32: PROPOSED DRAINAGE DETAILS SHEET 4 | E32: C01 | I32: C02 | J32: C03
B34: CDY-XX-XX-DR-D-Ss_50_35-0060 | C34: PROPOSED WATERCOURSE DIVERSION | E34: C01 | H34: C02 | J34: C03
B55: Distribution
B56: Initials | C56: Company | D56: Number of Copies
B57: bim 360 | D57: 1 | E57: 1 | F57: 1 | G57: 1 | H57: 1 | I57: 1 | J57: 1 | K57: 1 | L57: 1 | M57: 1 | N57: 1 | O57: 1
B58: THP | J58: 1
B59: RHP | J59: 1
C60: Anglian Water | V60: 1
B61: A.G | C61: Aspect | V61: 1
B62: K.C | C62: CamfordCM | V62: 1
C71: Suitability / Issue Status | D71: A4 | E71: A4 | F71: C | G71: C | H71: C | I71: C | J71: C | K71: P | L71: C | M71: C | N71: C | O71: C
C72: Format | D72: E | E72: E | F72: E/O | J72: E/P | O72: E
B73: Key
B74: BS EN ISO 19650 Suitability S0 = WIP Sn = Shared (Non Contractural) An = Published (Contractural) CR = Construction Record
B75: or Issue Status I = Information P = Preliminary T = Tender A = Approval C = Construction B = As Built | K75: Format P = Paper E = Email O = Online D = DWG

Sheet 3 Structures Sheet 01
Z4: DOCUMENT ISSUE REGISTER
B5: Project | C5: ='99. Structures Input (NO PRINT)'!C5 -> Aldi Store, Diss
B6: Client | C6: ='99. Structures Input (NO PRINT)'!C6 -> Aldi Stores Ltd
B7: Project No. | C7: ='99. Structures Input (NO PRINT)'!C7 -> 13175
B8: Sheet No. | C8: =RIGHT(CELL("FILENAME",A1),LEN(CELL("FILENAME",A1))-FIND("]",CELL("FILENAME",A1))) -> 3 Structures Sheet 01 | D8: Issue Date
B9: Document No. | C9: Document Title | D9: ='99. Structures Input (NO PRINT)'!D9 -> 22.02.24 | E9: ='99. Structures Input (NO PRINT)'!E9 -> 22.03.24 | F9: ='99. Structures Input (NO PRINT)'!F9 -> 23.04.24 | G9: ='99. Structures Input (NO PRINT)'!G9 -> 27.06.24 | H9: ='99. Structures Input (NO PRINT)'!H9 -> 12.07.24 | I9: ='99. Structures Input (NO PRINT)'!I9 -> 31.07.24 | J9: ='99. Structures Input (NO PRINT)'!J9 -> 07.10.24 | K9: ='99. Structures Input (NO PRINT)'!K9 -> 29.10.24 | ... BC9: ='99. Structures Input (NO PRINT)'!BC9 -> 0 | BD9: ='99. Structures Input (NO PRINT)'!BJ9 -> 0 | BE9: ='99. Structures Input (NO PRINT)'!BK9 -> 0 | BF9: ='99. Structures Input (NO PRINT)'!BL9 -> 0 | BG9: ='99. Structures Input (NO PRINT)'!BM9 -> 0 | BH9: ='99. Structures Input (NO PRINT)'!BN9 -> 0 | BI9: ='99. Structures Input (NO PRINT)'!BO9 -> 0 | BJ9: ='99. Structures Input (NO PRINT)'!BP9 -> 0 | BK9: ='99. Structures Input (NO PRINT)'!BQ9 -> 0 | ... BX9: ='99. Structures Input (NO PRINT)'!CD9 -> 0
B10: ='99. Structures Input (NO PRINT)'!B10 -> 79-E1597-CDY-XX-XX-M3-S-Ss_20_10_00-0001 | C10: ='99. Structures Input (NO PRINT)'!C10 -> REVIT MODEL COVER SHEET | D10: ='99. Structures Input (NO PRINT)'!D10 -> P01 | E10: ='99. Structures Input (NO PRINT)'!E10 -> P02 | F10: ='99. Structures Input (NO PRINT)'!F10 -> C01 | G10: ='99. Structures Input (NO PRINT)'!G10 -> C02 | H10: ='99. Structures Input (NO PRINT)'!H10 -> 0 | I10: ='99. Structures Input (NO PRINT)'!I10 -> 0 | ... BC10: ='99. Structures Input (NO PRINT)'!BC10 -> 0 | BD10: ='99. Structures Input (NO PRINT)'!BJ10 -> 0 | BE10: ='99. Structures Input (NO PRINT)'!BK10 -> 0 | BF10: ='99. Structures Input (NO PRINT)'!BL10 -> 0 | BG10: ='99. Structures Input (NO PRINT)'!BM10 -> 0 | BH10: ='99. Structures Input (NO PRINT)'!BN10 -> 0 | BI10: ='99. Structures Input (NO PRINT)'!BO10 -> 0 | BJ10: ='99. Structures Input (NO PRINT)'!BP10 -> 0 | BK10: ='99. Structures Input (NO PRINT)'!BQ10 -> 0 | ... BX10: ='99. Structures Input (NO PRINT)'!CD10 -> 0
B11: ='99. Structures Input (NO PRINT)'!B11 -> 79-E1597-CDY-XX-FN-DR-S-Ss_20_10_00-0200 | C11: ='99. Structures Input (NO PRINT)'!C11 -> PILE GENERAL ARRANGEMENT | D11: ='99. Structures Input (NO PRINT)'!D11 -> 0 | E11: ='99. Structures Input (NO PRINT)'!E11 -> 0 | F11: ='99. Structures Input (NO PRINT)'!F11 -> C01 | G11: ='99. Structures Input (NO PRINT)'!G11 -> C02 | H11: ='99. Structures Input (NO PRINT)'!H11 -> 0 | I11: ='99. Structures Input (NO PRINT)'!I11 -> C03 | ... BC11: ='99. Structures Input (NO PRINT)'!BC11 -> 0 | BD11: ='99. Structures Input (NO PRINT)'!BJ11 -> 0 | BE11: ='99. Structures Input (NO PRINT)'!BK11 -> 0 | BF11: ='99. Structures Input (NO PRINT)'!BL11 -> 0 | BG11: ='99. Structures Input (NO PRINT)'!BM11 -> 0 | BH11: ='99. Structures Input (NO PRINT)'!BN11 -> 0 | BI11: ='99. Structures Input (NO PRINT)'!BO11 -> 0 | BJ11: ='99. Structures Input (NO PRINT)'!BP11 -> 0 | BK11: ='99. Structures Input (NO PRINT)'!BQ11 -> 0 | ... BX11: ='99. Structures Input (NO PRINT)'!CD11 -> 0
B12: ='99. Structures Input (NO PRINT)'!B12 -> 79-E1597-CDY-XX-FN-DR-S-Ss_20_10_00-0201 | C12: ='99. Structures Input (NO PRINT)'!C12 -> PILE SCHEDULE | D12: ='99. Structures Input (NO PRINT)'!D12 -> 0 | E12: ='99. Structures Input (NO PRINT)'!E12 -> 0 | F12: ='99. Structures Input (NO PRINT)'!F12 -> 0 | G12: ='99. Structures Input (NO PRINT)'!G12 -> C01 | H12: ='99. Structures Input (NO PRINT)'!H12 -> 0 | I12: ='99. Structures Input (NO PRINT)'!I12 -> C02 | ... BC12: ='99. Structures Input (NO PRINT)'!BC12 -> 0 | BD12: ='99. Structures Input (NO PRINT)'!BJ12 -> 0 | BE12: ='99. Structures Input (NO PRINT)'!BK12 -> 0 | BF12: ='99. Structures Input (NO PRINT)'!BL12 -> 0 | BG12: ='99. Structures Input (NO PRINT)'!BM12 -> 0 | BH12: ='99. Structures Input (NO PRINT)'!BN12 -> 0 | BI12: ='99. Structures Input (NO PRINT)'!BO12 -> 0 | BJ12: ='99. Structures Input (NO PRINT)'!BP12 -> 0 | BK12: ='99. Structures Input (NO PRINT)'!BQ12 -> 0 | ... BX12: ='99. Structures Input (NO PRINT)'!CD12 -> 0
B13: ='99. Structures Input (NO PRINT)'!B13 -> 79-E1597-CDY-XX-FN-DR-S-Ss_20_10_00-0203 | C13: ='99. Structures Input (NO PRINT)'!C13 -> PILE CAP & GROUND BEAM GENERAL ARRANGEMENT | D13: ='99. Structures Input (NO PRINT)'!D13 -> 0 | E13: ='99. Structures Input (NO PRINT)'!E13 -> 0 | F13: ='99. Structures Input (NO PRINT)'!F13 -> C01 | G13: ='99. Structures Input (NO PRINT)'!G13 -> C02 | H13: ='99. Structures Input (NO PRINT)'!H13 -> 0 | I13: ='99. Structures Input (NO PRINT)'!I13 -> C03 | ... BC13: ='99. Structures Input (NO PRINT)'!BC13 -> 0 | BD13: ='99. Structures Input (NO PRINT)'!BJ13 -> 0 | BE13: ='99. Structures Input (NO PRINT)'!BK13 -> 0 | BF13: ='99. Structures Input (NO PRINT)'!BL13 -> 0 | BG13: ='99. Structures Input (NO PRINT)'!BM13 -> 0 | BH13: ='99. Structures Input (NO PRINT)'!BN13 -> 0 | BI13: ='99. Structures Input (NO PRINT)'!BO13 -> 0 | BJ13: ='99. Structures Input (NO PRINT)'!BP13 -> 0 | BK13: ='99. Structures Input (NO PRINT)'!BQ13 -> 0 | ... BX13: ='99. Structures Input (NO PRINT)'!CD13 -> 0
B14: ='99. Structures Input (NO PRINT)'!B14 -> 79-E1597-CDY-XX-FN-DR-S-Ss_20_10_00-0204 | C14: ='99. Structures Input (NO PRINT)'!C14 -> LORRY RAMP, PLANT SLAB AND DOUBLE POLE SIGN FOUNDATIONS | D14: ='99. Structures Input (NO PRINT)'!D14 -> 0 | E14: ='99. Structures Input (NO PRINT)'!E14 -> 0 | F14: ='99. Structures Input (NO PRINT)'!F14 -> C01 | G14: ='99. Structures Input (NO PRINT)'!G14 -> C02 | H14: ='99. Structures Input (NO PRINT)'!H14 -> 0 | I14: ='99. Structures Input (NO PRINT)'!I14 -> C03 | ... BC14: ='99. Structures Input (NO PRINT)'!BC14 -> 0 | BD14: ='99. Structures Input (NO PRINT)'!BJ14 -> 0 | BE14: ='99. Structures Input (NO PRINT)'!BK14 -> 0 | BF14: ='99. Structures Input (NO PRINT)'!BL14 -> 0 | BG14: ='99. Structures Input (NO PRINT)'!BM14 -> 0 | BH14: ='99. Structures Input (NO PRINT)'!BN14 -> 0 | BI14: ='99. Structures Input (NO PRINT)'!BO14 -> 0 | BJ14: ='99. Structures Input (NO PRINT)'!BP14 -> 0 | BK14: ='99. Structures Input (NO PRINT)'!BQ14 -> 0 | ... BX14: ='99. Structures Input (NO PRINT)'!CD14 -> 0
B15: ='99. Structures Input (NO PRINT)'!B15 -> 79-E1597-CDY-XX-FN-DR-S-Ss_20_10_00-0205 | C15: ='99. Structures Input (NO PRINT)'!C15 -> FOUNDATION DETAILS SHEET 01 | D15: ='99. Structures Input (NO PRINT)'!D15 -> 0 | E15: ='99. Structures Input (NO PRINT)'!E15 -> 0 | F15: ='99. Structures Input (NO PRINT)'!F15 -> C01 | G15: ='99. Structures Input (NO PRINT)'!G15 -> C02 | H15: ='99. Structures Input (NO PRINT)'!H15 -> 0 | I15: ='99. Structures Input (NO PRINT)'!I15 -> C03 | ... BC15: ='99. Structures Input (NO PRINT)'!BC15 -> 0 | BD15: ='99. Structures Input (NO PRINT)'!BJ15 -> 0 | BE15: ='99. Structures Input (NO PRINT)'!BK15 -> 0 | BF15: ='99. Structures Input (NO PRINT)'!BL15 -> 0 | BG15: ='99. Structures Input (NO PRINT)'!BM15 -> 0 | BH15: ='99. Structures Input (NO PRINT)'!BN15 -> 0 | BI15: ='99. Structures Input (NO PRINT)'!BO15 -> 0 | BJ15: ='99. Structures Input (NO PRINT)'!BP15 -> 0 | BK15: ='99. Structures Input (NO PRINT)'!BQ15 -> 0 | ... BX15: ='99. Structures Input (NO PRINT)'!CD15 -> 0
B16: ='99. Structures Input (NO PRINT)'!B16 -> 79-E1597-CDY-XX-FN-DR-S-Ss_20_10_00-0206 | C16: ='99. Structures Input (NO PRINT)'!C16 -> SHEET PILE GA & DETAILS | D16: ='99. Structures Input (NO PRINT)'!D16 -> 0 | E16: ='99. Structures Input (NO PRINT)'!E16 -> 0 | F16: ='99. Structures Input (NO PRINT)'!F16 -> 0 | G16: ='99. Structures Input (NO PRINT)'!G16 -> 0 | H16: ='99. Structures Input (NO PRINT)'!H16 -> 0 | I16: ='99. Structures Input (NO PRINT)'!I16 -> 0 | ... BC16: ='99. Structures Input (NO PRINT)'!BC16 -> 0 | BD16: ='99. Structures Input (NO PRINT)'!BJ16 -> 0 | BE16: ='99. Structures Input (NO PRINT)'!BK16 -> 0 | BF16: ='99. Structures Input (NO PRINT)'!BL16 -> 0 | BG16: ='99. Structures Input (NO PRINT)'!BM16 -> 0 | BH16: ='99. Structures Input (NO PRINT)'!BN16 -> 0 | BI16: ='99. Structures Input (NO PRINT)'!BO16 -> 0 | BJ16: ='99. Structures Input (NO PRINT)'!BP16 -> 0 | BK16: ='99. Structures Input (NO PRINT)'!BQ16 -> 0 | ... BX16: ='99. Structures Input (NO PRINT)'!CD16 -> 0
B17: ='99. Structures Input (NO PRINT)'!B17 -> 79-E1597-CDY-XX-00-DR-S-Ss_20_10_00-0210 | C17: ='99. Structures Input (NO PRINT)'!C17 -> GROUND FLOOR SLAB GENERAL ARRANGEMENT | D17: ='99. Structures Input (NO PRINT)'!D17 -> 0 | E17: ='99. Structures Input (NO PRINT)'!E17 -> 0 | F17: ='99. Structures Input (NO PRINT)'!F17 -> C01 | G17: ='99. Structures Input (NO PRINT)'!G17 -> C02 | H17: ='99. Structures Input (NO PRINT)'!H17 -> 0 | I17: ='99. Structures Input (NO PRINT)'!I17 -> C03 | ... BC17: ='99. Structures Input (NO PRINT)'!BC17 -> 0 | BD17: ='99. Structures Input (NO PRINT)'!BJ17 -> 0 | BE17: ='99. Structures Input (NO PRINT)'!BK17 -> 0 | BF17: ='99. Structures Input (NO PRINT)'!BL17 -> 0 | BG17: ='99. Structures Input (NO PRINT)'!BM17 -> 0 | BH17: ='99. Structures Input (NO PRINT)'!BN17 -> 0 | BI17: ='99. Structures Input (NO PRINT)'!BO17 -> 0 | BJ17: ='99. Structures Input (NO PRINT)'!BP17 -> 0 | BK17: ='99. Structures Input (NO PRINT)'!BQ17 -> 0 | ... BX17: ='99. Structures Input (NO PRINT)'!CD17 -> 0
B18: ='99. Structures Input (NO PRINT)'!B18 -> 79-E1597-CDY-XX-00-DR-S-Ss_20_10_00-0211 | C18: ='99. Structures Input (NO PRINT)'!C18 -> GROUND FLOOR SLAB DETAILS SHEET 01 | D18: ='99. Structures Input (NO PRINT)'!D18 -> 0 | E18: ='99. Structures Input (NO PRINT)'!E18 -> 0 | F18: ='99. Structures Input (NO PRINT)'!F18 -> C01 | G18: ='99. Structures Input (NO PRINT)'!G18 -> C02 | H18: ='99. Structures Input (NO PRINT)'!H18 -> 0 | I18: ='99. Structures Input (NO PRINT)'!I18 -> C03 | ... BC18: ='99. Structures Input (NO PRINT)'!BC18 -> 0 | BD18: ='99. Structures Input (NO PRINT)'!BJ18 -> 0 | BE18: ='99. Structures Input (NO PRINT)'!BK18 -> 0 | BF18: ='99. Structures Input (NO PRINT)'!BL18 -> 0 | BG18: ='99. Structures Input (NO PRINT)'!BM18 -> 0 | BH18: ='99. Structures Input (NO PRINT)'!BN18 -> 0 | BI18: ='99. Structures Input (NO PRINT)'!BO18 -> 0 | BJ18: ='99. Structures Input (NO PRINT)'!BP18 -> 0 | BK18: ='99. Structures Input (NO PRINT)'!BQ18 -> 0 | ... BX18: ='99. Structures Input (NO PRINT)'!CD18 -> 0
B19: ='99. Structures Input (NO PRINT)'!B19 -> 79-E1597-CDY-XX-00-DR-S-Ss_20_10_00-0215 | C19: ='99. Structures Input (NO PRINT)'!C19 -> DOCK LEVELLER GA AND RC DETAILS | D19: ='99. Structures Input (NO PRINT)'!D19 -> 0 | E19: ='99. Structures Input (NO PRINT)'!E19 -> 0 | F19: ='99. Structures Input (NO PRINT)'!F19 -> C01 | G19: ='99. Structures Input (NO PRINT)'!G19 -> C02 | H19: ='99. Structures Input (NO PRINT)'!H19 -> 0 | I19: ='99. Structures Input (NO PRINT)'!I19 -> C03 | ... BC19: ='99. Structures Input (NO PRINT)'!BC19 -> 0 | BD19: ='99. Structures Input (NO PRINT)'!BJ19 -> 0 | BE19: ='99. Structures Input (NO PRINT)'!BK19 -> 0 | BF19: ='99. Structures Input (NO PRINT)'!BL19 -> 0 | BG19: ='99. Structures Input (NO PRINT)'!BM19 -> 0 | BH19: ='99. Structures Input (NO PRINT)'!BN19 -> 0 | BI19: ='99. Structures Input (NO PRINT)'!BO19 -> 0 | BJ19: ='99. Structures Input (NO PRINT)'!BP19 -> 0 | BK19: ='99. Structures Input (NO PRINT)'!BQ19 -> 0 | ... BX19: ='99. Structures Input (NO PRINT)'!CD19 -> 0
B20: ='99. Structures Input (NO PRINT)'!B20 -> 79-E1597-CDY-XX-00-DR-S-Ss_20_10_00-0220 | C20: ='99. Structures Input (NO PRINT)'!C20 -> MASONRY TIE GENERAL ARRANGEMENT | D20: ='99. Structures Input (NO PRINT)'!D20 -> 0 | E20: ='99. Structures Input (NO PRINT)'!E20 -> 0 | F20: ='99. Structures Input (NO PRINT)'!F20 -> 0 | G20: ='99. Structures Input (NO PRINT)'!G20 -> 0 | H20: ='99. Structures Input (NO PRINT)'!H20 -> 0 | I20: ='99. Structures Input (NO PRINT)'!I20 -> C01 | ... BC20: ='99. Structures Input (NO PRINT)'!BC20 -> 0 | BD20: ='99. Structures Input (NO PRINT)'!BJ20 -> 0 | BE20: ='99. Structures Input (NO PRINT)'!BK20 -> 0 | BF20: ='99. Structures Input (NO PRINT)'!BL20 -> 0 | BG20: ='99. Structures Input (NO PRINT)'!BM20 -> 0 | BH20: ='99. Structures Input (NO PRINT)'!BN20 -> 0 | BI20: ='99. Structures Input (NO PRINT)'!BO20 -> 0 | BJ20: ='99. Structures Input (NO PRINT)'!BP20 -> 0 | BK20: ='99. Structures Input (NO PRINT)'!BQ20 -> 0 | ... BX20: ='99. Structures Input (NO PRINT)'!CD20 -> 0
B21: ='99. Structures Input (NO PRINT)'!B21 -> 79-E1597-CDY-XX-00-DR-S-Ss_20_10_00-0221 | C21: ='99. Structures Input (NO PRINT)'!C21 -> MASONRY TIE DETAILS | D21: ='99. Structures Input (NO PRINT)'!D21 -> 0 | E21: ='99. Structures Input (NO PRINT)'!E21 -> 0 | F21: ='99. Structures Input (NO PRINT)'!F21 -> 0 | G21: ='99. Structures Input (NO PRINT)'!G21 -> 0 | H21: ='99. Structures Input (NO PRINT)'!H21 -> 0 | I21: ='99. Structures Input (NO PRINT)'!I21 -> C01 | ... BC21: ='99. Structures Input (NO PRINT)'!BC21 -> 0 | BD21: ='99. Structures Input (NO PRINT)'!BJ21 -> 0 | BE21: ='99. Structures Input (NO PRINT)'!BK21 -> 0 | BF21: ='99. Structures Input (NO PRINT)'!BL21 -> 0 | BG21: ='99. Structures Input (NO PRINT)'!BM21 -> 0 | BH21: ='99. Structures Input (NO PRINT)'!BN21 -> 0 | BI21: ='99. Structures Input (NO PRINT)'!BO21 -> 0 | BJ21: ='99. Structures Input (NO PRINT)'!BP21 -> 0 | BK21: ='99. Structures Input (NO PRINT)'!BQ21 -> 0 | ... BX21: ='99. Structures Input (NO PRINT)'!CD21 -> 0
... B53: ='99. Structures Input (NO PRINT)'!B53 -> 0 | C53: ='99. Structures Input (NO PRINT)'!C53 -> 0 | D53: ='99. Structures Input (NO PRINT)'!D53 -> 0 | E53: ='99. Structures Input (NO PRINT)'!E53 -> 0 | F53: ='99. Structures Input (NO PRINT)'!F53 -> 0 | G53: ='99. Structures Input (NO PRINT)'!G53 -> 0 | H53: ='99. Structures Input (NO PRINT)'!H53 -> 0 | I53: ='99. Structures Input (NO PRINT)'!I53 -> 0 | ... BC53: ='99. Structures Input (NO PRINT)'!BC53 -> 0 | BD53: ='99. Structures Input (NO PRINT)'!BJ53 -> 0 | BE53: ='99. Structures Input (NO PRINT)'!BK53 -> 0 | BF53: ='99. Structures Input (NO PRINT)'!BL53 -> 0 | BG53: ='99. Structures Input (NO PRINT)'!BM53 -> 0 | BH53: ='99. Structures Input (NO PRINT)'!BN53 -> 0 | BI53: ='99. Structures Input (NO PRINT)'!BO53 -> 0 | BJ53: ='99. Structures Input (NO PRINT)'!BP53 -> 0 | BK53: ='99. Structures Input (NO PRINT)'!BQ53 -> 0 | ... BX53: ='99. Structures Input (NO PRINT)'!CD53 -> 0
B54: Distribution
B55: Initials | C55: Company | D55: Number of Copies
B56: ='99. Structures Input (NO PRINT)'!B557 -> BIM360 | C56: ='99. Structures Input (NO PRINT)'!C557 -> 0 | D56: ='99. Structures Input (NO PRINT)'!D557 -> 1 | E56: ='99. Structures Input (NO PRINT)'!E557 -> 1 | F56: ='99. Structures Input (NO PRINT)'!F557 -> 1 | G56: ='99. Structures Input (NO PRINT)'!G557 -> 1 | H56: ='99. Structures Input (NO PRINT)'!H557 -> 1 | I56: ='99. Structures Input (NO PRINT)'!I557 -> 1 | ... BC56: ='99. Structures Input (NO PRINT)'!BC557 -> 0 | BD56: ='99. Structures Input (NO PRINT)'!BJ557 -> 0 | BE56: ='99. Structures Input (NO PRINT)'!BK557 -> 0 | BF56: ='99. Structures Input (NO PRINT)'!BL557 -> 0 | BG56: ='99. Structures Input (NO PRINT)'!BM557 -> 0 | BH56: ='99. Structures Input (NO PRINT)'!BN557 -> 0 | BI56: ='99. Structures Input (NO PRINT)'!BO557 -> 0 | BJ56: ='99. Structures Input (NO PRINT)'!BP557 -> 0 | BK56: ='99. Structures Input (NO PRINT)'!BQ557 -> 0 | ... BX56: ='99. Structures Input (NO PRINT)'!CD557 -> 0
B57: ='99. Structures Input (NO PRINT)'!B558 -> THP | C57: ='99. Structures Input (NO PRINT)'!C558 -> 0 | D57: ='99. Structures Input (NO PRINT)'!D558 -> 1 | E57: ='99. Structures Input (NO PRINT)'!E558 -> 1 | F57: ='99. Structures Input (NO PRINT)'!F558 -> 1 | G57: ='99. Structures Input (NO PRINT)'!G558 -> 1 | H57: ='99. Structures Input (NO PRINT)'!H558 -> 1 | I57: ='99. Structures Input (NO PRINT)'!I558 -> 1 | ... BC57: ='99. Structures Input (NO PRINT)'!BC558 -> 0 | BD57: ='99. Structures Input (NO PRINT)'!BJ558 -> 0 | BE57: ='99. Structures Input (NO PRINT)'!BK558 -> 0 | BF57: ='99. Structures Input (NO PRINT)'!BL558 -> 0 | BG57: ='99. Structures Input (NO PRINT)'!BM558 -> 0 | BH57: ='99. Structures Input (NO PRINT)'!BN558 -> 0 | BI57: ='99. Structures Input (NO PRINT)'!BO558 -> 0 | BJ57: ='99. Structures Input (NO PRINT)'!BP558 -> 0 | BK57: ='99. Structures Input (NO PRINT)'!BQ558 -> 0 | ... BX57: ='99. Structures Input (NO PRINT)'!CD558 -> 0
B58: ='99. Structures Input (NO PRINT)'!B559 -> RHP | C58: ='99. Structures Input (NO PRINT)'!C559 -> 0 | D58: ='99. Structures Input (NO PRINT)'!D559 -> 1 | E58: ='99. Structures Input (NO PRINT)'!E559 -> 1 | F58: ='99. Structures Input (NO PRINT)'!F559 -> 1 | G58: ='99. Structures Input (NO PRINT)'!G559 -> 1 | H58: ='99. Structures Input (NO PRINT)'!H559 -> 1 | I58: ='99. Structures Input (NO PRINT)'!I559 -> 1 | ... BC58: ='99. Structures Input (NO PRINT)'!BC559 -> 0 | BD58: ='99. Structures Input (NO PRINT)'!BJ559 -> 0 | BE58: ='99. Structures Input (NO PRINT)'!BK559 -> 0 | BF58: ='99. Structures Input (NO PRINT)'!BL559 -> 0 | BG58: ='99. Structures Input (NO PRINT)'!BM559 -> 0 | BH58: ='99. Structures Input (NO PRINT)'!BN559 -> 0 | BI58: ='99. Structures Input (NO PRINT)'!BO559 -> 0 | BJ58: ='99. Structures Input (NO PRINT)'!BP559 -> 0 | BK58: ='99. Structures Input (NO PRINT)'!BQ559 -> 0 | ... BX58: ='99. Structures Input (NO PRINT)'!CD559 -> 0
B59: ='99. Structures Input (NO PRINT)'!B560 -> 0 | G59: ='99. Structures Input (NO PRINT)'!G560 -> 0 | H59: ='99. Structures Input (NO PRINT)'!H560 -> 0 | I59: ='99. Structures Input (NO PRINT)'!I560 -> 0 | J59: ='99. Structures Input (NO PRINT)'!J560 -> 0 | K59: ='99. Structures Input (NO PRINT)'!K560 -> 0 | L59: ='99. Structures Input (NO PRINT)'!L560 -> 0 | M59: ='99. Structures Input (NO PRINT)'!M560 -> 0 | N59: ='99. Structures Input (NO PRINT)'!N560 -> 0 | ... BC59: ='99. Structures Input (NO PRINT)'!BC560 -> 0 | BD59: ='99. Structures Input (NO PRINT)'!BJ560 -> 0 | BE59: ='99. Structures Input (NO PRINT)'!BK560 -> 0 | BF59: ='99. Structures Input (NO PRINT)'!BL560 -> 0 | BG59: ='99. Structures Input (NO PRINT)'!BM560 -> 0 | BH59: ='99. Structures Input (NO PRINT)'!BN560 -> 0 | BI59: ='99. Structures Input (NO PRINT)'!BO560 -> 0 | BJ59: ='99. Structures Input (NO PRINT)'!BP560 -> 0 | BK59: ='99. Structures Input (NO PRINT)'!BQ560 -> 0 | ... BX59: ='99. Structures Input (NO PRINT)'!CD560 -> 0
B60: ='99. Structures Input (NO PRINT)'!B561 -> 0 | G60: ='99. Structures Input (NO PRINT)'!G561 -> 0 | H60: ='99. Structures Input (NO PRINT)'!H561 -> 0 | I60: ='99. Structures Input (NO PRINT)'!I561 -> 0 | J60: ='99. Structures Input (NO PRINT)'!J561 -> 0 | K60: ='99. Structures Input (NO PRINT)'!K561 -> 0 | L60: ='99. Structures Input (NO PRINT)'!L561 -> 0 | M60: ='99. Structures Input (NO PRINT)'!M561 -> 0 | N60: ='99. Structures Input (NO PRINT)'!N561 -> 0 | ... BC60: ='99. Structures Input (NO PRINT)'!BC561 -> 0 | BD60: ='99. Structures Input (NO PRINT)'!BJ561 -> 0 | BE60: ='99. Structures Input (NO PRINT)'!BK561 -> 0 | BF60: ='99. Structures Input (NO PRINT)'!BL561 -> 0 | BG60: ='99. Structures Input (NO PRINT)'!BM561 -> 0 | BH60: ='99. Structures Input (NO PRINT)'!BN561 -> 0 | BI60: ='99. Structures Input (NO PRINT)'!BO561 -> 0 | BJ60: ='99. Structures Input (NO PRINT)'!BP561 -> 0 | BK60: ='99. Structures Input (NO PRINT)'!BQ561 -> 0 | ... BX60: ='99. Structures Input (NO PRINT)'!CD561 -> 0
B61: ='99. Structures Input (NO PRINT)'!B562 -> 0 | C61: ='99. Structures Input (NO PRINT)'!C562 -> 0 | D61: ='99. Structures Input (NO PRINT)'!D562 -> 0 | E61: ='99. Structures Input (NO PRINT)'!E562 -> 0 | F61: ='99. Structures Input (NO PRINT)'!F562 -> 0 | G61: ='99. Structures Input (NO PRINT)'!G562 -> 0 | H61: ='99. Structures Input (NO PRINT)'!H562 -> 0 | I61: ='99. Structures Input (NO PRINT)'!I562 -> 0 | ... BC61: ='99. Structures Input (NO PRINT)'!BC562 -> 0 | BD61: ='99. Structures Input (NO PRINT)'!BJ562 -> 0 | BE61: ='99. Structures Input (NO PRINT)'!BK562 -> 0 | BF61: ='99. Structures Input (NO PRINT)'!BL562 -> 0 | BG61: ='99. Structures Input (NO PRINT)'!BM562 -> 0 | BH61: ='99. Structures Input (NO PRINT)'!BN562 -> 0 | BI61: ='99. Structures Input (NO PRINT)'!BO562 -> 0 | BJ61: ='99. Structures Input (NO PRINT)'!BP562 -> 0 | BK61: ='99. Structures Input (NO PRINT)'!BQ562 -> 0 | ... BX61: ='99. Structures Input (NO PRINT)'!CD562 -> 0
B62: ='99. Structures Input (NO PRINT)'!B563 -> 0 | C62: ='99. Structures Input (NO PRINT)'!C563 -> 0 | D62: ='99. Structures Input (NO PRINT)'!D563 -> 0 | E62: ='99. Structures Input (NO PRINT)'!E563 -> 0 | F62: ='99. Structures Input (NO PRINT)'!F563 -> 0 | G62: ='99. Structures Input (NO PRINT)'!G563 -> 0 | H62: ='99. Structures Input (NO PRINT)'!H563 -> 0 | I62: ='99. Structures Input (NO PRINT)'!I563 -> 0 | ... BC62: ='99. Structures Input (NO PRINT)'!BC563 -> 0 | BD62: ='99. Structures Input (NO PRINT)'!BJ563 -> 0 | BE62: ='99. Structures Input (NO PRINT)'!BK563 -> 0 | BF62: ='99. Structures Input (NO PRINT)'!BL563 -> 0 | BG62: ='99. Structures Input (NO PRINT)'!BM563 -> 0 | BH62: ='99. Structures Input (NO PRINT)'!BN563 -> 0 | BI62: ='99. Structures Input (NO PRINT)'!BO563 -> 0 | BJ62: ='99. Structures Input (NO PRINT)'!BP563 -> 0 | BK62: ='99. Structures Input (NO PRINT)'!BQ563 -> 0 | ... BX62: ='99. Structures Input (NO PRINT)'!CD563 -> 0
B63: ='99. Structures Input (NO PRINT)'!B564 -> 0 | C63: ='99. Structures Input (NO PRINT)'!C564 -> 0 | D63: ='99. Structures Input (NO PRINT)'!D564 -> 0 | E63: ='99. Structures Input (NO PRINT)'!E564 -> 0 | F63: ='99. Structures Input (NO PRINT)'!F564 -> 0 | G63: ='99. Structures Input (NO PRINT)'!G564 -> 0 | H63: ='99. Structures Input (NO PRINT)'!H564 -> 0 | I63: ='99. Structures Input (NO PRINT)'!I564 -> 0 | ... BC63: ='99. Structures Input (NO PRINT)'!BC564 -> 0 | BD63: ='99. Structures Input (NO PRINT)'!BJ564 -> 0 | BE63: ='99. Structures Input (NO PRINT)'!BK564 -> 0 | BF63: ='99. Structures Input (NO PRINT)'!BL564 -> 0 | BG63: ='99. Structures Input (NO PRINT)'!BM564 -> 0 | BH63: ='99. Structures Input (NO PRINT)'!BN564 -> 0 | BI63: ='99. Structures Input (NO PRINT)'!BO564 -> 0 | BJ63: ='99. Structures Input (NO PRINT)'!BP564 -> 0 | BK63: ='99. Structures Input (NO PRINT)'!BQ564 -> 0 | ... BX63: ='99. Structures Input (NO PRINT)'!CD564 -> 0
B64: ='99. Structures Input (NO PRINT)'!B565 -> 0 | C64: ='99. Structures Input (NO PRINT)'!C565 -> 0 | D64: ='99. Structures Input (NO PRINT)'!D565 -> 0 | E64: ='99. Structures Input (NO PRINT)'!E565 -> 0 | F64: ='99. Structures Input (NO PRINT)'!F565 -> 0 | G64: ='99. Structures Input (NO PRINT)'!G565 -> 0 | H64: ='99. Structures Input (NO PRINT)'!H565 -> 0 | I64: ='99. Structures Input (NO PRINT)'!I565 -> 0 | ... BC64: ='99. Structures Input (NO PRINT)'!BC565 -> 0 | BD64: ='99. Structures Input (NO PRINT)'!BJ565 -> 0 | BE64: ='99. Structures Input (NO PRINT)'!BK565 -> 0 | BF64: ='99. Structures Input (NO PRINT)'!BL565 -> 0 | BG64: ='99. Structures Input (NO PRINT)'!BM565 -> 0 | BH64: ='99. Structures Input (NO PRINT)'!BN565 -> 0 | BI64: ='99. Structures Input (NO PRINT)'!BO565 -> 0 | BJ64: ='99. Structures Input (NO PRINT)'!BP565 -> 0 | BK64: ='99. Structures Input (NO PRINT)'!BQ565 -> 0 | ... BX64: ='99. Structures Input (NO PRINT)'!CD565 -> 0
B65: ='99. Structures Input (NO PRINT)'!B566 -> 0 | C65: ='99. Structures Input (NO PRINT)'!C566 -> 0 | D65: ='99. Structures Input (NO PRINT)'!D566 -> 0 | E65: ='99. Structures Input (NO PRINT)'!E566 -> 0 | F65: ='99. Structures Input (NO PRINT)'!F566 -> 0 | G65: ='99. Structures Input (NO PRINT)'!G566 -> 0 | H65: ='99. Structures Input (NO PRINT)'!H566 -> 0 | I65: ='99. Structures Input (NO PRINT)'!I566 -> 0 | ... BC65: ='99. Structures Input (NO PRINT)'!BC566 -> 0 | BD65: ='99. Structures Input (NO PRINT)'!BJ566 -> 0 | BE65: ='99. Structures Input (NO PRINT)'!BK566 -> 0 | BF65: ='99. Structures Input (NO PRINT)'!BL566 -> 0 | BG65: ='99. Structures Input (NO PRINT)'!BM566 -> 0 | BH65: ='99. Structures Input (NO PRINT)'!BN566 -> 0 | BI65: ='99. Structures Input (NO PRINT)'!BO566 -> 0 | BJ65: ='99. Structures Input (NO PRINT)'!BP566 -> 0 | BK65: ='99. Structures Input (NO PRINT)'!BQ566 -> 0 | ... BX65: ='99. Structures Input (NO PRINT)'!CD566 -> 0
B66: ='99. Structures Input (NO PRINT)'!B567 -> 0 | C66: ='99. Structures Input (NO PRINT)'!C567 -> 0 | D66: ='99. Structures Input (NO PRINT)'!D567 -> 0 | E66: ='99. Structures Input (NO PRINT)'!E567 -> 0 | F66: ='99. Structures Input (NO PRINT)'!F567 -> 0 | G66: ='99. Structures Input (NO PRINT)'!G567 -> 0 | H66: ='99. Structures Input (NO PRINT)'!H567 -> 0 | I66: ='99. Structures Input (NO PRINT)'!I567 -> 0 | ... BC66: ='99. Structures Input (NO PRINT)'!BC567 -> 0 | BD66: ='99. Structures Input (NO PRINT)'!BJ567 -> 0 | BE66: ='99. Structures Input (NO PRINT)'!BK567 -> 0 | BF66: ='99. Structures Input (NO PRINT)'!BL567 -> 0 | BG66: ='99. Structures Input (NO PRINT)'!BM567 -> 0 | BH66: ='99. Structures Input (NO PRINT)'!BN567 -> 0 | BI66: ='99. Structures Input (NO PRINT)'!BO567 -> 0 | BJ66: ='99. Structures Input (NO PRINT)'!BP567 -> 0 | BK66: ='99. Structures Input (NO PRINT)'!BQ567 -> 0 | ... BX66: ='99. Structures Input (NO PRINT)'!CD567 -> 0
B67: ='99. Structures Input (NO PRINT)'!B568 -> 0 | C67: ='99. Structures Input (NO PRINT)'!C568 -> 0 | D67: ='99. Structures Input (NO PRINT)'!D568 -> 0 | E67: ='99. Structures Input (NO PRINT)'!E568 -> 0 | F67: ='99. Structures Input (NO PRINT)'!F568 -> 0 | G67: ='99. Structures Input (NO PRINT)'!G568 -> 0 | H67: ='99. Structures Input (NO PRINT)'!H568 -> 0 | I67: ='99. Structures Input (NO PRINT)'!I568 -> 0 | ... BC67: ='99. Structures Input (NO PRINT)'!BC568 -> 0 | BD67: ='99. Structures Input (NO PRINT)'!BJ568 -> 0 | BE67: ='99. Structures Input (NO PRINT)'!BK568 -> 0 | BF67: ='99. Structures Input (NO PRINT)'!BL568 -> 0 | BG67: ='99. Structures Input (NO PRINT)'!BM568 -> 0 | BH67: ='99. Structures Input (NO PRINT)'!BN568 -> 0 | BI67: ='99. Structures Input (NO PRINT)'!BO568 -> 0 | BJ67: ='99. Structures Input (NO PRINT)'!BP568 -> 0 | BK67: ='99. Structures Input (NO PRINT)'!BQ568 -> 0 | ... BX67: ='99. Structures Input (NO PRINT)'!CD568 -> 0
B68: ='99. Structures Input (NO PRINT)'!B569 -> 0 | C68: ='99. Structures Input (NO PRINT)'!C569 -> 0 | D68: ='99. Structures Input (NO PRINT)'!D569 -> 0 | E68: ='99. Structures Input (NO PRINT)'!E569 -> 0 | F68: ='99. Structures Input (NO PRINT)'!F569 -> 0 | G68: ='99. Structures Input (NO PRINT)'!G569 -> 0 | H68: ='99. Structures Input (NO PRINT)'!H569 -> 0 | I68: ='99. Structures Input (NO PRINT)'!I569 -> 0 | ... BC68: ='99. Structures Input (NO PRINT)'!BC569 -> 0 | BD68: ='99. Structures Input (NO PRINT)'!BJ569 -> 0 | BE68: ='99. Structures Input (NO PRINT)'!BK569 -> 0 | BF68: ='99. Structures Input (NO PRINT)'!BL569 -> 0 | BG68: ='99. Structures Input (NO PRINT)'!BM569 -> 0 | BH68: ='99. Structures Input (NO PRINT)'!BN569 -> 0 | BI68: ='99. Structures Input (NO PRINT)'!BO569 -> 0 | BJ68: ='99. Structures Input (NO PRINT)'!BP569 -> 0 | BK68: ='99. Structures Input (NO PRINT)'!BQ569 -> 0 | ... BX68: ='99. Structures Input (NO PRINT)'!CD569 -> 0
B69: ='99. Structures Input (NO PRINT)'!B570 -> 0 | C69: ='99. Structures Input (NO PRINT)'!C570 -> 0 | D69: ='99. Structures Input (NO PRINT)'!D570 -> 0 | E69: ='99. Structures Input (NO PRINT)'!E570 -> 0 | F69: ='99. Structures Input (NO PRINT)'!F570 -> 0 | G69: ='99. Structures Input (NO PRINT)'!G570 -> 0 | H69: ='99. Structures Input (NO PRINT)'!H570 -> 0 | I69: ='99. Structures Input (NO PRINT)'!I570 -> 0 | ... BC69: ='99. Structures Input (NO PRINT)'!BC570 -> 0 | BD69: ='99. Structures Input (NO PRINT)'!BJ570 -> 0 | BE69: ='99. Structures Input (NO PRINT)'!BK570 -> 0 | BF69: ='99. Structures Input (NO PRINT)'!BL570 -> 0 | BG69: ='99. Structures Input (NO PRINT)'!BM570 -> 0 | BH69: ='99. Structures Input (NO PRINT)'!BN570 -> 0 | BI69: ='99. Structures Input (NO PRINT)'!BO570 -> 0 | BJ69: ='99. Structures Input (NO PRINT)'!BP570 -> 0 | BK69: ='99. Structures Input (NO PRINT)'!BQ570 -> 0 | ... BX69: ='99. Structures Input (NO PRINT)'!CD570 -> 0
C70: Suitability / Issue Status | D70: ='99. Structures Input (NO PRINT)'!D571 -> A4 | E70: ='99. Structures Input (NO PRINT)'!E571 -> A4 | F70: ='99. Structures Input (NO PRINT)'!F571 -> A5 | G70: ='99. Structures Input (NO PRINT)'!G571 -> A5 | H70: ='99. Structures Input (NO PRINT)'!H571 -> A5 | I70: ='99. Structures Input (NO PRINT)'!I571 -> A5 | J70: ='99. Structures Input (NO PRINT)'!J571 -> A5 | K70: ='99. Structures Input (NO PRINT)'!K571 -> A5 | ... BC70: ='99. Structures Input (NO PRINT)'!BC571 -> 0 | BD70: ='99. Structures Input (NO PRINT)'!BJ571 -> 0 | BE70: ='99. Structures Input (NO PRINT)'!BK571 -> 0 | BF70: ='99. Structures Input (NO PRINT)'!BL571 -> 0 | BG70: ='99. Structures Input (NO PRINT)'!BM571 -> 0 | BH70: ='99. Structures Input (NO PRINT)'!BN571 -> 0 | BI70: ='99. Structures Input (NO PRINT)'!BO571 -> 0 | BJ70: ='99. Structures Input (NO PRINT)'!BP571 -> 0 | BK70: ='99. Structures Input (NO PRINT)'!BQ571 -> 0 | ... BX70: ='99. Structures Input (NO PRINT)'!CD571 -> 0
C71: Format | D71: ='99. Structures Input (NO PRINT)'!D572 -> O | E71: ='99. Structures Input (NO PRINT)'!E572 -> O | F71: ='99. Structures Input (NO PRINT)'!F572 -> O | G71: ='99. Structures Input (NO PRINT)'!G572 -> O | H71: ='99. Structures Input (NO PRINT)'!H572 -> O | I71: ='99. Structures Input (NO PRINT)'!I572 -> O | J71: ='99. Structures Input (NO PRINT)'!J572 -> O | K71: ='99. Structures Input (NO PRINT)'!K572 -> O | ... BC71: ='99. Structures Input (NO PRINT)'!BC572 -> 0 | BD71: ='99. Structures Input (NO PRINT)'!BJ572 -> 0 | BE71: ='99. Structures Input (NO PRINT)'!BK572 -> 0 | BF71: ='99. Structures Input (NO PRINT)'!BL572 -> 0 | BG71: ='99. Structures Input (NO PRINT)'!BM572 -> 0 | BH71: ='99. Structures Input (NO PRINT)'!BN572 -> 0 | BI71: ='99. Structures Input (NO PRINT)'!BO572 -> 0 | BJ71: ='99. Structures Input (NO PRINT)'!BP572 -> 0 | BK71: ='99. Structures Input (NO PRINT)'!BQ572 -> 0 | ... BX71: ='99. Structures Input (NO PRINT)'!CD572 -> 0
B72: Key
B73: BS EN ISO 19650 Suitability S0 = WIP Sn = Shared (Non Contractural) An = Published (Contractural) CR = Construction Record
B74: or Issue Status I = Information P = Preliminary T = Tender A = Approval C = Construction B = As Built | K74: Format P = Paper E = Email O = Online D = DWG

Sheet 4. Structures Sheet 02
Z4: DOCUMENT ISSUE REGISTER
B5: Project | C5: ='99. Structures Input (NO PRINT)'!C5 -> Aldi Store, Diss
B6: Client | C6: ='99. Structures Input (NO PRINT)'!C6 -> Aldi Stores Ltd
B7: Project No. | C7: ='99. Structures Input (NO PRINT)'!C7 -> 13175
B8: Sheet No. | C8: =RIGHT(CELL("FILENAME",A1),LEN(CELL("FILENAME",A1))-FIND("]",CELL("FILENAME",A1))) -> 4. Structures Sheet 02 | D8: Issue Date
B9: Document No. | C9: Document Title | D9: ='99. Structures Input (NO PRINT)'!D9 -> 22.02.24 | E9: ='99. Structures Input (NO PRINT)'!E9 -> 22.03.24 | F9: ='99. Structures Input (NO PRINT)'!F9 -> 23.04.24 | G9: ='99. Structures Input (NO PRINT)'!G9 -> 27.06.24 | H9: ='99. Structures Input (NO PRINT)'!H9 -> 12.07.24 | I9: ='99. Structures Input (NO PRINT)'!I9 -> 31.07.24 | J9: ='99. Structures Input (NO PRINT)'!J9 -> 07.10.24 | K9: ='99. Structures Input (NO PRINT)'!K9 -> 29.10.24 | ... BC9: ='99. Structures Input (NO PRINT)'!BC9 -> 0 | BD9: ='99. Structures Input (NO PRINT)'!BJ9 -> 0 | BE9: ='99. Structures Input (NO PRINT)'!BK9 -> 0 | BF9: ='99. Structures Input (NO PRINT)'!BL9 -> 0 | BG9: ='99. Structures Input (NO PRINT)'!BM9 -> 0 | BH9: ='99. Structures Input (NO PRINT)'!BN9 -> 0 | BI9: ='99. Structures Input (NO PRINT)'!BO9 -> 0 | BJ9: ='99. Structures Input (NO PRINT)'!BP9 -> 0 | BK9: ='99. Structures Input (NO PRINT)'!BQ9 -> 0 | ... BX9: ='99. Structures Input (NO PRINT)'!CD9 -> 0
B10: ='99. Structures Input (NO PRINT)'!B54 -> 0 | C10: ='99. Structures Input (NO PRINT)'!C54 -> 0 | D10: ='99. Structures Input (NO PRINT)'!D54 -> 0 | E10: ='99. Structures Input (NO PRINT)'!E54 -> 0 | F10: ='99. Structures Input (NO PRINT)'!F54 -> 0 | G10: ='99. Structures Input (NO PRINT)'!G54 -> 0 | H10: ='99. Structures Input (NO PRINT)'!H54 -> 0 | I10: ='99. Structures Input (NO PRINT)'!I54 -> 0 | ... BC10: ='99. Structures Input (NO PRINT)'!BC54 -> 0 | BD10: ='99. Structures Input (NO PRINT)'!BJ54 -> 0 | BE10: ='99. Structures Input (NO PRINT)'!BK54 -> 0 | BF10: ='99. Structures Input (NO PRINT)'!BL54 -> 0 | BG10: ='99. Structures Input (NO PRINT)'!BM54 -> 0 | BH10: ='99. Structures Input (NO PRINT)'!BN54 -> 0 | BI10: ='99. Structures Input (NO PRINT)'!BO54 -> 0 | BJ10: ='99. Structures Input (NO PRINT)'!BP54 -> 0 | BK10: ='99. Structures Input (NO PRINT)'!BQ54 -> 0 | ... BX10: ='99. Structures Input (NO PRINT)'!CD54 -> 0
B11: ='99. Structures Input (NO PRINT)'!B55 -> 0 | C11: ='99. Structures Input (NO PRINT)'!C55 -> 0 | D11: ='99. Structures Input (NO PRINT)'!D55 -> 0 | E11: ='99. Structures Input (NO PRINT)'!E55 -> 0 | F11: ='99. Structures Input (NO PRINT)'!F55 -> 0 | G11: ='99. Structures Input (NO PRINT)'!G55 -> 0 | H11: ='99. Structures Input (NO PRINT)'!H55 -> 0 | I11: ='99. Structures Input (NO PRINT)'!I55 -> 0 | ... BC11: ='99. Structures Input (NO PRINT)'!BC55 -> 0 | BD11: ='99. Structures Input (NO PRINT)'!BJ55 -> 0 | BE11: ='99. Structures Input (NO PRINT)'!BK55 -> 0 | BF11: ='99. Structures Input (NO PRINT)'!BL55 -> 0 | BG11: ='99. Structures Input (NO PRINT)'!BM55 -> 0 | BH11: ='99. Structures Input (NO PRINT)'!BN55 -> 0 | BI11: ='99. Structures Input (NO PRINT)'!BO55 -> 0 | BJ11: ='99. Structures Input (NO PRINT)'!BP55 -> 0 | BK11: ='99. Structures Input (NO PRINT)'!BQ55 -> 0 | ... BX11: ='99. Structures Input (NO PRINT)'!CD55 -> 0
B12: ='99. Structures Input (NO PRINT)'!B56 -> 0 | C12: ='99. Structures Input (NO PRINT)'!C56 -> 0 | D12: ='99. Structures Input (NO PRINT)'!D56 -> 0 | E12: ='99. Structures Input (NO PRINT)'!E56 -> 0 | F12: ='99. Structures Input (NO PRINT)'!F56 -> 0 | G12: ='99. Structures Input (NO PRINT)'!G56 -> 0 | H12: ='99. Structures Input (NO PRINT)'!H56 -> 0 | I12: ='99. Structures Input (NO PRINT)'!I56 -> 0 | ... BC12: ='99. Structures Input (NO PRINT)'!BC56 -> 0 | BD12: ='99. Structures Input (NO PRINT)'!BJ56 -> 0 | BE12: ='99. Structures Input (NO PRINT)'!BK56 -> 0 | BF12: ='99. Structures Input (NO PRINT)'!BL56 -> 0 | BG12: ='99. Structures Input (NO PRINT)'!BM56 -> 0 | BH12: ='99. Structures Input (NO PRINT)'!BN56 -> 0 | BI12: ='99. Structures Input (NO PRINT)'!BO56 -> 0 | BJ12: ='99. Structures Input (NO PRINT)'!BP56 -> 0 | BK12: ='99. Structures Input (NO PRINT)'!BQ56 -> 0 | ... BX12: ='99. Structures Input (NO PRINT)'!CD56 -> 0
B13: ='99. Structures Input (NO PRINT)'!B57 -> 0 | C13: ='99. Structures Input (NO PRINT)'!C57 -> 0 | D13: ='99. Structures Input (NO PRINT)'!D57 -> 0 | E13: ='99. Structures Input (NO PRINT)'!E57 -> 0 | F13: ='99. Structures Input (NO PRINT)'!F57 -> 0 | G13: ='99. Structures Input (NO PRINT)'!G57 -> 0 | H13: ='99. Structures Input (NO PRINT)'!H57 -> 0 | I13: ='99. Structures Input (NO PRINT)'!I57 -> 0 | ... BC13: ='99. Structures Input (NO PRINT)'!BC57 -> 0 | BD13: ='99. Structures Input (NO PRINT)'!BJ57 -> 0 | BE13: ='99. Structures Input (NO PRINT)'!BK57 -> 0 | BF13: ='99. Structures Input (NO PRINT)'!BL57 -> 0 | BG13: ='99. Structures Input (NO PRINT)'!BM57 -> 0 | BH13: ='99. Structures Input (NO PRINT)'!BN57 -> 0 | BI13: ='99. Structures Input (NO PRINT)'!BO57 -> 0 | BJ13: ='99. Structures Input (NO PRINT)'!BP57 -> 0 | BK13: ='99. Structures Input (NO PRINT)'!BQ57 -> 0 | ... BX13: ='99. Structures Input (NO PRINT)'!CD57 -> 0
B14: ='99. Structures Input (NO PRINT)'!B58 -> 0 | C14: ='99. Structures Input (NO PRINT)'!C58 -> 0 | D14: ='99. Structures Input (NO PRINT)'!D58 -> 0 | E14: ='99. Structures Input (NO PRINT)'!E58 -> 0 | F14: ='99. Structures Input (NO PRINT)'!F58 -> 0 | G14: ='99. Structures Input (NO PRINT)'!G58 -> 0 | H14: ='99. Structures Input (NO PRINT)'!H58 -> 0 | I14: ='99. Structures Input (NO PRINT)'!I58 -> 0 | ... BC14: ='99. Structures Input (NO PRINT)'!BC58 -> 0 | BD14: ='99. Structures Input (NO PRINT)'!BJ58 -> 0 | BE14: ='99. Structures Input (NO PRINT)'!BK58 -> 0 | BF14: ='99. Structures Input (NO PRINT)'!BL58 -> 0 | BG14: ='99. Structures Input (NO PRINT)'!BM58 -> 0 | BH14: ='99. Structures Input (NO PRINT)'!BN58 -> 0 | BI14: ='99. Structures Input (NO PRINT)'!BO58 -> 0 | BJ14: ='99. Structures Input (NO PRINT)'!BP58 -> 0 | BK14: ='99. Structures Input (NO PRINT)'!BQ58 -> 0 | ... BX14: ='99. Structures Input (NO PRINT)'!CD58 -> 0
B15: ='99. Structures Input (NO PRINT)'!B59 -> 0 | C15: ='99. Structures Input (NO PRINT)'!C59 -> 0 | D15: ='99. Structures Input (NO PRINT)'!D59 -> 0 | E15: ='99. Structures Input (NO PRINT)'!E59 -> 0 | F15: ='99. Structures Input (NO PRINT)'!F59 -> 0 | G15: ='99. Structures Input (NO PRINT)'!G59 -> 0 | H15: ='99. Structures Input (NO PRINT)'!H59 -> 0 | I15: ='99. Structures Input (NO PRINT)'!I59 -> 0 | ... BC15: ='99. Structures Input (NO PRINT)'!BC59 -> 0 | BD15: ='99. Structures Input (NO PRINT)'!BJ59 -> 0 | BE15: ='99. Structures Input (NO PRINT)'!BK59 -> 0 | BF15: ='99. Structures Input (NO PRINT)'!BL59 -> 0 | BG15: ='99. Structures Input (NO PRINT)'!BM59 -> 0 | BH15: ='99. Structures Input (NO PRINT)'!BN59 -> 0 | BI15: ='99. Structures Input (NO PRINT)'!BO59 -> 0 | BJ15: ='99. Structures Input (NO PRINT)'!BP59 -> 0 | BK15: ='99. Structures Input (NO PRINT)'!BQ59 -> 0 | ... BX15: ='99. Structures Input (NO PRINT)'!CD59 -> 0
B16: ='99. Structures Input (NO PRINT)'!B60 -> 0 | C16: ='99. Structures Input (NO PRINT)'!C60 -> 0 | D16: ='99. Structures Input (NO PRINT)'!D60 -> 0 | E16: ='99. Structures Input (NO PRINT)'!E60 -> 0 | F16: ='99. Structures Input (NO PRINT)'!F60 -> 0 | G16: ='99. Structures Input (NO PRINT)'!G60 -> 0 | H16: ='99. Structures Input (NO PRINT)'!H60 -> 0 | I16: ='99. Structures Input (NO PRINT)'!I60 -> 0 | ... BC16: ='99. Structures Input (NO PRINT)'!BC60 -> 0 | BD16: ='99. Structures Input (NO PRINT)'!BJ60 -> 0 | BE16: ='99. Structures Input (NO PRINT)'!BK60 -> 0 | BF16: ='99. Structures Input (NO PRINT)'!BL60 -> 0 | BG16: ='99. Structures Input (NO PRINT)'!BM60 -> 0 | BH16: ='99. Structures Input (NO PRINT)'!BN60 -> 0 | BI16: ='99. Structures Input (NO PRINT)'!BO60 -> 0 | BJ16: ='99. Structures Input (NO PRINT)'!BP60 -> 0 | BK16: ='99. Structures Input (NO PRINT)'!BQ60 -> 0 | ... BX16: ='99. Structures Input (NO PRINT)'!CD60 -> 0
B17: ='99. Structures Input (NO PRINT)'!B61 -> 0 | C17: ='99. Structures Input (NO PRINT)'!C61 -> 0 | D17: ='99. Structures Input (NO PRINT)'!D61 -> 0 | E17: ='99. Structures Input (NO PRINT)'!E61 -> 0 | F17: ='99. Structures Input (NO PRINT)'!F61 -> 0 | G17: ='99. Structures Input (NO PRINT)'!G61 -> 0 | H17: ='99. Structures Input (NO PRINT)'!H61 -> 0 | I17: ='99. Structures Input (NO PRINT)'!I61 -> 0 | ... BC17: ='99. Structures Input (NO PRINT)'!BC61 -> 0 | BD17: ='99. Structures Input (NO PRINT)'!BJ61 -> 0 | BE17: ='99. Structures Input (NO PRINT)'!BK61 -> 0 | BF17: ='99. Structures Input (NO PRINT)'!BL61 -> 0 | BG17: ='99. Structures Input (NO PRINT)'!BM61 -> 0 | BH17: ='99. Structures Input (NO PRINT)'!BN61 -> 0 | BI17: ='99. Structures Input (NO PRINT)'!BO61 -> 0 | BJ17: ='99. Structures Input (NO PRINT)'!BP61 -> 0 | BK17: ='99. Structures Input (NO PRINT)'!BQ61 -> 0 | ... BX17: ='99. Structures Input (NO PRINT)'!CD61 -> 0
B18: ='99. Structures Input (NO PRINT)'!B62 -> 0 | C18: ='99. Structures Input (NO PRINT)'!C62 -> 0 | D18: ='99. Structures Input (NO PRINT)'!D62 -> 0 | E18: ='99. Structures Input (NO PRINT)'!E62 -> 0 | F18: ='99. Structures Input (NO PRINT)'!F62 -> 0 | G18: ='99. Structures Input (NO PRINT)'!G62 -> 0 | H18: ='99. Structures Input (NO PRINT)'!H62 -> 0 | I18: ='99. Structures Input (NO PRINT)'!I62 -> 0 | ... BC18: ='99. Structures Input (NO PRINT)'!BC62 -> 0 | BD18: ='99. Structures Input (NO PRINT)'!BJ62 -> 0 | BE18: ='99. Structures Input (NO PRINT)'!BK62 -> 0 | BF18: ='99. Structures Input (NO PRINT)'!BL62 -> 0 | BG18: ='99. Structures Input (NO PRINT)'!BM62 -> 0 | BH18: ='99. Structures Input (NO PRINT)'!BN62 -> 0 | BI18: ='99. Structures Input (NO PRINT)'!BO62 -> 0 | BJ18: ='99. Structures Input (NO PRINT)'!BP62 -> 0 | BK18: ='99. Structures Input (NO PRINT)'!BQ62 -> 0 | ... BX18: ='99. Structures Input (NO PRINT)'!CD62 -> 0
B19: ='99. Structures Input (NO PRINT)'!B63 -> 0 | C19: ='99. Structures Input (NO PRINT)'!C63 -> 0 | D19: ='99. Structures Input (NO PRINT)'!D63 -> 0 | E19: ='99. Structures Input (NO PRINT)'!E63 -> 0 | F19: ='99. Structures Input (NO PRINT)'!F63 -> 0 | G19: ='99. Structures Input (NO PRINT)'!G63 -> 0 | H19: ='99. Structures Input (NO PRINT)'!H63 -> 0 | I19: ='99. Structures Input (NO PRINT)'!I63 -> 0 | ... BC19: ='99. Structures Input (NO PRINT)'!BC63 -> 0 | BD19: ='99. Structures Input (NO PRINT)'!BJ63 -> 0 | BE19: ='99. Structures Input (NO PRINT)'!BK63 -> 0 | BF19: ='99. Structures Input (NO PRINT)'!BL63 -> 0 | BG19: ='99. Structures Input (NO PRINT)'!BM63 -> 0 | BH19: ='99. Structures Input (NO PRINT)'!BN63 -> 0 | BI19: ='99. Structures Input (NO PRINT)'!BO63 -> 0 | BJ19: ='99. Structures Input (NO PRINT)'!BP63 -> 0 | BK19: ='99. Structures Input (NO PRINT)'!BQ63 -> 0 | ... BX19: ='99. Structures Input (NO PRINT)'!CD63 -> 0
B20: ='99. Structures Input (NO PRINT)'!B64 -> 0 | C20: ='99. Structures Input (NO PRINT)'!C64 -> 0 | D20: ='99. Structures Input (NO PRINT)'!D64 -> 0 | E20: ='99. Structures Input (NO PRINT)'!E64 -> 0 | F20: ='99. Structures Input (NO PRINT)'!F64 -> 0 | G20: ='99. Structures Input (NO PRINT)'!G64 -> 0 | H20: ='99. Structures Input (NO PRINT)'!H64 -> 0 | I20: ='99. Structures Input (NO PRINT)'!I64 -> 0 | ... BC20: ='99. Structures Input (NO PRINT)'!BC64 -> 0 | BD20: ='99. Structures Input (NO PRINT)'!BJ64 -> 0 | BE20: ='99. Structures Input (NO PRINT)'!BK64 -> 0 | BF20: ='99. Structures Input (NO PRINT)'!BL64 -> 0 | BG20: ='99. Structures Input (NO PRINT)'!BM64 -> 0 | BH20: ='99. Structures Input (NO PRINT)'!BN64 -> 0 | BI20: ='99. Structures Input (NO PRINT)'!BO64 -> 0 | BJ20: ='99. Structures Input (NO PRINT)'!BP64 -> 0 | BK20: ='99. Structures Input (NO PRINT)'!BQ64 -> 0 | ... BX20: ='99. Structures Input (NO PRINT)'!CD64 -> 0
B21: ='99. Structures Input (NO PRINT)'!B65 -> 0 | C21: ='99. Structures Input (NO PRINT)'!C65 -> 0 | D21: ='99. Structures Input (NO PRINT)'!D65 -> 0 | E21: ='99. Structures Input (NO PRINT)'!E65 -> 0 | F21: ='99. Structures Input (NO PRINT)'!F65 -> 0 | G21: ='99. Structures Input (NO PRINT)'!G65 -> 0 | H21: ='99. Structures Input (NO PRINT)'!H65 -> 0 | I21: ='99. Structures Input (NO PRINT)'!I65 -> 0 | ... BC21: ='99. Structures Input (NO PRINT)'!BC65 -> 0 | BD21: ='99. Structures Input (NO PRINT)'!BJ65 -> 0 | BE21: ='99. Structures Input (NO PRINT)'!BK65 -> 0 | BF21: ='99. Structures Input (NO PRINT)'!BL65 -> 0 | BG21: ='99. Structures Input (NO PRINT)'!BM65 -> 0 | BH21: ='99. Structures Input (NO PRINT)'!BN65 -> 0 | BI21: ='99. Structures Input (NO PRINT)'!BO65 -> 0 | BJ21: ='99. Structures Input (NO PRINT)'!BP65 -> 0 | BK21: ='99. Structures Input (NO PRINT)'!BQ65 -> 0 | ... BX21: ='99. Structures Input (NO PRINT)'!CD65 -> 0
... B53: ='99. Structures Input (NO PRINT)'!B97 -> 0 | C53: ='99. Structures Input (NO PRINT)'!C97 -> 0 | D53: ='99. Structures Input (NO PRINT)'!D97 -> 0 | E53: ='99. Structures Input (NO PRINT)'!E97 -> 0 | F53: ='99. Structures Input (NO PRINT)'!F97 -> 0 | G53: ='99. Structures Input (NO PRINT)'!G97 -> 0 | H53: ='99. Structures Input (NO PRINT)'!H97 -> 0 | I53: ='99. Structures Input (NO PRINT)'!I97 -> 0 | ... BC53: ='99. Structures Input (NO PRINT)'!BC97 -> 0 | BD53: ='99. Structures Input (NO PRINT)'!BJ97 -> 0 | BE53: ='99. Structures Input (NO PRINT)'!BK97 -> 0 | BF53: ='99. Structures Input (NO PRINT)'!BL97 -> 0 | BG53: ='99. Structures Input (NO PRINT)'!BM97 -> 0 | BH53: ='99. Structures Input (NO PRINT)'!BN97 -> 0 | BI53: ='99. Structures Input (NO PRINT)'!BO97 -> 0 | BJ53: ='99. Structures Input (NO PRINT)'!BP97 -> 0 | BK53: ='99. Structures Input (NO PRINT)'!BQ97 -> 0 | ... BX53: ='99. Structures Input (NO PRINT)'!CD97 -> 0
B54: Distribution
B55: Initials | C55: Company | D55: Number of Copies
B56: ='99. Structures Input (NO PRINT)'!B557 -> BIM360 | C56: ='99. Structures Input (NO PRINT)'!C557 -> 0 | D56: ='99. Structures Input (NO PRINT)'!D557 -> 1 | E56: ='99. Structures Input (NO PRINT)'!E557 -> 1 | F56: ='99. Structures Input (NO PRINT)'!F557 -> 1 | G56: ='99. Structures Input (NO PRINT)'!G557 -> 1 | H56: ='99. Structures Input (NO PRINT)'!H557 -> 1 | I56: ='99. Structures Input (NO PRINT)'!I557 -> 1 | ... BC56: ='99. Structures Input (NO PRINT)'!BC557 -> 0 | BD56: ='99. Structures Input (NO PRINT)'!BJ557 -> 0 | BE56: ='99. Structures Input (NO PRINT)'!BK557 -> 0 | BF56: ='99. Structures Input (NO PRINT)'!BL557 -> 0 | BG56: ='99. Structures Input (NO PRINT)'!BM557 -> 0 | BH56: ='99. Structures Input (NO PRINT)'!BN557 -> 0 | BI56: ='99. Structures Input (NO PRINT)'!BO557 -> 0 | BJ56: ='99. Structures Input (NO PRINT)'!BP557 -> 0 | BK56: ='99. Structures Input (NO PRINT)'!BQ557 -> 0 | ... BX56: ='99. Structures Input (NO PRINT)'!CD557 -> 0
B57: ='99. Structures Input (NO PRINT)'!B558 -> THP | C57: ='99. Structures Input (NO PRINT)'!C558 -> 0 | D57: ='99. Structures Input (NO PRINT)'!D558 -> 1 | E57: ='99. Structures Input (NO PRINT)'!E558 -> 1 | F57: ='99. Structures Input (NO PRINT)'!F558 -> 1 | G57: ='99. Structures Input (NO PRINT)'!G558 -> 1 | H57: ='99. Structures Input (NO PRINT)'!H558 -> 1 | I57: ='99. Structures Input (NO PRINT)'!I558 -> 1 | ... BC57: ='99. Structures Input (NO PRINT)'!BC558 -> 0 | BD57: ='99. Structures Input (NO PRINT)'!BJ558 -> 0 | BE57: ='99. Structures Input (NO PRINT)'!BK558 -> 0 | BF57: ='99. Structures Input (NO PRINT)'!BL558 -> 0 | BG57: ='99. Structures Input (NO PRINT)'!BM558 -> 0 | BH57: ='99. Structures Input (NO PRINT)'!BN558 -> 0 | BI57: ='99. Structures Input (NO PRINT)'!BO558 -> 0 | BJ57: ='99. Structures Input (NO PRINT)'!BP558 -> 0 | BK57: ='99. Structures Input (NO PRINT)'!BQ558 -> 0 | ... BX57: ='99. Structures Input (NO PRINT)'!CD558 -> 0
B58: ='99. Structures Input (NO PRINT)'!B559 -> RHP | C58: ='99. Structures Input (NO PRINT)'!C559 -> 0 | D58: ='99. Structures Input (NO PRINT)'!D559 -> 1 | E58: ='99. Structures Input (NO PRINT)'!E559 -> 1 | F58: ='99. Structures Input (NO PRINT)'!F559 -> 1 | G58: ='99. Structures Input (NO PRINT)'!G559 -> 1 | H58: ='99. Structures Input (NO PRINT)'!H559 -> 1 | I58: ='99. Structures Input (NO PRINT)'!I559 -> 1 | ... BC58: ='99. Structures Input (NO PRINT)'!BC559 -> 0 | BD58: ='99. Structures Input (NO PRINT)'!BJ559 -> 0 | BE58: ='99. Structures Input (NO PRINT)'!BK559 -> 0 | BF58: ='99. Structures Input (NO PRINT)'!BL559 -> 0 | BG58: ='99. Structures Input (NO PRINT)'!BM559 -> 0 | BH58: ='99. Structures Input (NO PRINT)'!BN559 -> 0 | BI58: ='99. Structures Input (NO PRINT)'!BO559 -> 0 | BJ58: ='99. Structures Input (NO PRINT)'!BP559 -> 0 | BK58: ='99. Structures Input (NO PRINT)'!BQ559 -> 0 | ... BX58: ='99. Structures Input (NO PRINT)'!CD559 -> 0
B59: ='99. Structures Input (NO PRINT)'!B560 -> 0 | C59: ='99. Structures Input (NO PRINT)'!C560 -> 0 | D59: ='99. Structures Input (NO PRINT)'!D560 -> 0 | E59: ='99. Structures Input (NO PRINT)'!E560 -> 0 | F59: ='99. Structures Input (NO PRINT)'!F560 -> 0 | G59: ='99. Structures Input (NO PRINT)'!G560 -> 0 | H59: ='99. Structures Input (NO PRINT)'!H560 -> 0 | I59: ='99. Structures Input (NO PRINT)'!I560 -> 0 | ... BC59: ='99. Structures Input (NO PRINT)'!BC560 -> 0 | BD59: ='99. Structures Input (NO PRINT)'!BJ560 -> 0 | BE59: ='99. Structures Input (NO PRINT)'!BK560 -> 0 | BF59: ='99. Structures Input (NO PRINT)'!BL560 -> 0 | BG59: ='99. Structures Input (NO PRINT)'!BM560 -> 0 | BH59: ='99. Structures Input (NO PRINT)'!BN560 -> 0 | BI59: ='99. Structures Input (NO PRINT)'!BO560 -> 0 | BJ59: ='99. Structures Input (NO PRINT)'!BP560 -> 0 | BK59: ='99. Structures Input (NO PRINT)'!BQ560 -> 0 | ... BX59: ='99. Structures Input (NO PRINT)'!CD560 -> 0
B60: ='99. Structures Input (NO PRINT)'!B561 -> 0 | C60: ='99. Structures Input (NO PRINT)'!C561 -> 0 | D60: ='99. Structures Input (NO PRINT)'!D561 -> 0 | E60: ='99. Structures Input (NO PRINT)'!E561 -> 0 | F60: ='99. Structures Input (NO PRINT)'!F561 -> 0 | G60: ='99. Structures Input (NO PRINT)'!G561 -> 0 | H60: ='99. Structures Input (NO PRINT)'!H561 -> 0 | I60: ='99. Structures Input (NO PRINT)'!I561 -> 0 | ... BC60: ='99. Structures Input (NO PRINT)'!BC561 -> 0 | BD60: ='99. Structures Input (NO PRINT)'!BJ561 -> 0 | BE60: ='99. Structures Input (NO PRINT)'!BK561 -> 0 | BF60: ='99. Structures Input (NO PRINT)'!BL561 -> 0 | BG60: ='99. Structures Input (NO PRINT)'!BM561 -> 0 | BH60: ='99. Structures Input (NO PRINT)'!BN561 -> 0 | BI60: ='99. Structures Input (NO PRINT)'!BO561 -> 0 | BJ60: ='99. Structures Input (NO PRINT)'!BP561 -> 0 | BK60: ='99. Structures Input (NO PRINT)'!BQ561 -> 0 | ... BX60: ='99. Structures Input (NO PRINT)'!CD561 -> 0
B61: ='99. Structures Input (NO PRINT)'!B562 -> 0 | C61: ='99. Structures Input (NO PRINT)'!C562 -> 0 | D61: ='99. Structures Input (NO PRINT)'!D562 -> 0 | E61: ='99. Structures Input (NO PRINT)'!E562 -> 0 | F61: ='99. Structures Input (NO PRINT)'!F562 -> 0 | G61: ='99. Structures Input (NO PRINT)'!G562 -> 0 | H61: ='99. Structures Input (NO PRINT)'!H562 -> 0 | I61: ='99. Structures Input (NO PRINT)'!I562 -> 0 | ... BC61: ='99. Structures Input (NO PRINT)'!BC562 -> 0 | BD61: ='99. Structures Input (NO PRINT)'!BJ562 -> 0 | BE61: ='99. Structures Input (NO PRINT)'!BK562 -> 0 | BF61: ='99. Structures Input (NO PRINT)'!BL562 -> 0 | BG61: ='99. Structures Input (NO PRINT)'!BM562 -> 0 | BH61: ='99. Structures Input (NO PRINT)'!BN562 -> 0 | BI61: ='99. Structures Input (NO PRINT)'!BO562 -> 0 | BJ61: ='99. Structures Input (NO PRINT)'!BP562 -> 0 | BK61: ='99. Structures Input (NO PRINT)'!BQ562 -> 0 | ... BX61: ='99. Structures Input (NO PRINT)'!CD562 -> 0
B62: ='99. Structures Input (NO PRINT)'!B563 -> 0 | C62: ='99. Structures Input (NO PRINT)'!C563 -> 0 | D62: ='99. Structures Input (NO PRINT)'!D563 -> 0 | E62: ='99. Structures Input (NO PRINT)'!E563 -> 0 | F62: ='99. Structures Input (NO PRINT)'!F563 -> 0 | G62: ='99. Structures Input (NO PRINT)'!G563 -> 0 | H62: ='99. Structures Input (NO PRINT)'!H563 -> 0 | I62: ='99. Structures Input (NO PRINT)'!I563 -> 0 | ... BC62: ='99. Structures Input (NO PRINT)'!BC563 -> 0 | BD62: ='99. Structures Input (NO PRINT)'!BJ563 -> 0 | BE62: ='99. Structures Input (NO PRINT)'!BK563 -> 0 | BF62: ='99. Structures Input (NO PRINT)'!BL563 -> 0 | BG62: ='99. Structures Input (NO PRINT)'!BM563 -> 0 | BH62: ='99. Structures Input (NO PRINT)'!BN563 -> 0 | BI62: ='99. Structures Input (NO PRINT)'!BO563 -> 0 | BJ62: ='99. Structures Input (NO PRINT)'!BP563 -> 0 | BK62: ='99. Structures Input (NO PRINT)'!BQ563 -> 0 | ... BX62: ='99. Structures Input (NO PRINT)'!CD563 -> 0
B63: ='99. Structures Input (NO PRINT)'!B564 -> 0 | C63: ='99. Structures Input (NO PRINT)'!C564 -> 0 | D63: ='99. Structures Input (NO PRINT)'!D564 -> 0 | E63: ='99. Structures Input (NO PRINT)'!E564 -> 0 | F63: ='99. Structures Input (NO PRINT)'!F564 -> 0 | G63: ='99. Structures Input (NO PRINT)'!G564 -> 0 | H63: ='99. Structures Input (NO PRINT)'!H564 -> 0 | I63: ='99. Structures Input (NO PRINT)'!I564 -> 0 | ... BC63: ='99. Structures Input (NO PRINT)'!BC564 -> 0 | BD63: ='99. Structures Input (NO PRINT)'!BJ564 -> 0 | BE63: ='99. Structures Input (NO PRINT)'!BK564 -> 0 | BF63: ='99. Structures Input (NO PRINT)'!BL564 -> 0 | BG63: ='99. Structures Input (NO PRINT)'!BM564 -> 0 | BH63: ='99. Structures Input (NO PRINT)'!BN564 -> 0 | BI63: ='99. Structures Input (NO PRINT)'!BO564 -> 0 | BJ63: ='99. Structures Input (NO PRINT)'!BP564 -> 0 | BK63: ='99. Structures Input (NO PRINT)'!BQ564 -> 0 | ... BX63: ='99. Structures Input (NO PRINT)'!CD564 -> 0
B64: ='99. Structures Input (NO PRINT)'!B565 -> 0 | C64: ='99. Structures Input (NO PRINT)'!C565 -> 0 | D64: ='99. Structures Input (NO PRINT)'!D565 -> 0 | E64: ='99. Structures Input (NO PRINT)'!E565 -> 0 | F64: ='99. Structures Input (NO PRINT)'!F565 -> 0 | G64: ='99. Structures Input (NO PRINT)'!G565 -> 0 | H64: ='99. Structures Input (NO PRINT)'!H565 -> 0 | I64: ='99. Structures Input (NO PRINT)'!I565 -> 0 | ... BC64: ='99. Structures Input (NO PRINT)'!BC565 -> 0 | BD64: ='99. Structures Input (NO PRINT)'!BJ565 -> 0 | BE64: ='99. Structures Input (NO PRINT)'!BK565 -> 0 | BF64: ='99. Structures Input (NO PRINT)'!BL565 -> 0 | BG64: ='99. Structures Input (NO PRINT)'!BM565 -> 0 | BH64: ='99. Structures Input (NO PRINT)'!BN565 -> 0 | BI64: ='99. Structures Input (NO PRINT)'!BO565 -> 0 | BJ64: ='99. Structures Input (NO PRINT)'!BP565 -> 0 | BK64: ='99. Structures Input (NO PRINT)'!BQ565 -> 0 | ... BX64: ='99. Structures Input (NO PRINT)'!CD565 -> 0
B65: ='99. Structures Input (NO PRINT)'!B566 -> 0 | C65: ='99. Structures Input (NO PRINT)'!C566 -> 0 | D65: ='99. Structures Input (NO PRINT)'!D566 -> 0 | E65: ='99. Structures Input (NO PRINT)'!E566 -> 0 | F65: ='99. Structures Input (NO PRINT)'!F566 -> 0 | G65: ='99. Structures Input (NO PRINT)'!G566 -> 0 | H65: ='99. Structures Input (NO PRINT)'!H566 -> 0 | I65: ='99. Structures Input (NO PRINT)'!I566 -> 0 | ... BC65: ='99. Structures Input (NO PRINT)'!BC566 -> 0 | BD65: ='99. Structures Input (NO PRINT)'!BJ566 -> 0 | BE65: ='99. Structures Input (NO PRINT)'!BK566 -> 0 | BF65: ='99. Structures Input (NO PRINT)'!BL566 -> 0 | BG65: ='99. Structures Input (NO PRINT)'!BM566 -> 0 | BH65: ='99. Structures Input (NO PRINT)'!BN566 -> 0 | BI65: ='99. Structures Input (NO PRINT)'!BO566 -> 0 | BJ65: ='99. Structures Input (NO PRINT)'!BP566 -> 0 | BK65: ='99. Structures Input (NO PRINT)'!BQ566 -> 0 | ... BX65: ='99. Structures Input (NO PRINT)'!CD566 -> 0
B66: ='99. Structures Input (NO PRINT)'!B567 -> 0 | C66: ='99. Structures Input (NO PRINT)'!C567 -> 0 | D66: ='99. Structures Input (NO PRINT)'!D567 -> 0 | E66: ='99. Structures Input (NO PRINT)'!E567 -> 0 | F66: ='99. Structures Input (NO PRINT)'!F567 -> 0 | G66: ='99. Structures Input (NO PRINT)'!G567 -> 0 | H66: ='99. Structures Input (NO PRINT)'!H567 -> 0 | I66: ='99. Structures Input (NO PRINT)'!I567 -> 0 | ... BC66: ='99. Structures Input (NO PRINT)'!BC567 -> 0 | BD66: ='99. Structures Input (NO PRINT)'!BJ567 -> 0 | BE66: ='99. Structures Input (NO PRINT)'!BK567 -> 0 | BF66: ='99. Structures Input (NO PRINT)'!BL567 -> 0 | BG66: ='99. Structures Input (NO PRINT)'!BM567 -> 0 | BH66: ='99. Structures Input (NO PRINT)'!BN567 -> 0 | BI66: ='99. Structures Input (NO PRINT)'!BO567 -> 0 | BJ66: ='99. Structures Input (NO PRINT)'!BP567 -> 0 | BK66: ='99. Structures Input (NO PRINT)'!BQ567 -> 0 | ... BX66: ='99. Structures Input (NO PRINT)'!CD567 -> 0
B67: ='99. Structures Input (NO PRINT)'!B568 -> 0 | C67: ='99. Structures Input (NO PRINT)'!C568 -> 0 | D67: ='99. Structures Input (NO PRINT)'!D568 -> 0 | E67: ='99. Structures Input (NO PRINT)'!E568 -> 0 | F67: ='99. Structures Input (NO PRINT)'!F568 -> 0 | G67: ='99. Structures Input (NO PRINT)'!G568 -> 0 | H67: ='99. Structures Input (NO PRINT)'!H568 -> 0 | I67: ='99. Structures Input (NO PRINT)'!I568 -> 0 | ... BC67: ='99. Structures Input (NO PRINT)'!BC568 -> 0 | BD67: ='99. Structures Input (NO PRINT)'!BJ568 -> 0 | BE67: ='99. Structures Input (NO PRINT)'!BK568 -> 0 | BF67: ='99. Structures Input (NO PRINT)'!BL568 -> 0 | BG67: ='99. Structures Input (NO PRINT)'!BM568 -> 0 | BH67: ='99. Structures Input (NO PRINT)'!BN568 -> 0 | BI67: ='99. Structures Input (NO PRINT)'!BO568 -> 0 | BJ67: ='99. Structures Input (NO PRINT)'!BP568 -> 0 | BK67: ='99. Structures Input (NO PRINT)'!BQ568 -> 0 | ... BX67: ='99. Structures Input (NO PRINT)'!CD568 -> 0
